Workbook

Sheet Informe
IG3: Motivo de espera en Bahía | IH3: Regimen | II3: Tipo de Operación | IJ3: Supervisores de Muelle | IM3: Equipo Tisur | IO3: SERVICIOS A LIQUIDAR | IR3: Agencias | IS3: Equipos Terceros | IU3: Estado de la Mar | IW3: Recepción de la nave | IY3: 42551
B4: FORSUR-O-0050 | H4: Hrs Esp Bahia | I4: =C10-C9 -> 5.2923611 | N4: REVISIÓN-14 | IG4: Alistamiento de carga | IH4: IMPORTACION | II4: DESCARGA INDIRECTA | IJ4: JANNETT ALBITRES | IL4: OPERADOR TORRE VIGAN | IM4: TORRE VIGAN | IO4: ALQUILER DE ELEVADORA | IR4: INMARPAC | IS4: PAYLOADER | IU4: BUENO | IW4: EN BAHIA | IY4: Nombre del Trabajador | IZ4: Cargo
B5: Nave | D5: SKY KNIGHT | H5: Hrs Pre | I5: =C11-C10 -> 0.22152778 | L5: TIEMPOS MUERTOS | P5: TIEMPOS MUERTOS APN | T5: BODEGA | U5: EQUIPO | V5: PESO | W5: CANT. | IG5: Apertura de muelle | IH5: EXPORTACION | II5: DESCARGA DIRECTA | IJ5: JORGE HUERTA | IL5: OPERADOR TORRE BHULER | IM5: TORREBHULER | IO5: ALQUILER DE GRUA GOTTWALD | IR5: TRANSTOTAL | IS5: BOBCAT | IU5: MALO | IW5: EN MUELLE | IY5: ALBITRES VELASQUEZ, JANNET | IZ5: SUP. MUELLE | JB5: FIGUEROA FLORES,MARCO ANTONIO | JC5: GAVIERO
B6: Recalada | D6: 10841 | H6: Hrs Post | I6: =IF(C13="",0,C13-C12) -> 0.079166667 | L6: Detalle | N6: Tiempo | P6: Detalle | R6: Tiempo | T6: =IF($D$46="","",$D$46) -> BODEGA N°1 | U6: =IF($D$47="","",$D$47) -> EMBARQUE - LOTE 25105 | V6: =$D$103 -> 2095.6895 | W6: =$E$103 -> 0 | IG6: Espera de instrucciones | IH6: BOLIVIA EXPORTACION | II6: EMBARQUE INDIRECTO | IJ6: JESUS PASTOR | IL6: OPERADOR ELEVADORA 05 | IM6: ELEVADORA 05 TNS. | IO6: ALQUILER DE GRUA GROVE | IR6: RASAN | IS6: ELEVADORA | IU6: REGULAR | IY6: ALIAGA ARELA EVA | IZ6: TARJADOR | JB6: FIGUEROA RODRIGUEZ, EDER | JC6: GAVIERO
B7: Supervisor de Muelle | H7: Hrs Oper. | I7: =C12-C11 -> 1.1944444 | L7: Tisur | N7: =SUMIF('Serv. no Conf. - Horas Muertas'!$N$18:$N$66,"TISUR",'Serv. no Conf. - Horas Muertas'!$F$18:$F$66) -> 0.055555556 | P7: Agencia Marítima / Nave | R7: =SUMIF('Serv. no Conf. - Horas Muertas'!$O$72:$O$225,P7,'Serv. no Conf. - Horas Muertas'!$F$72:$F$225) -> 0 | T7: =IF($F$46="","",$F$46) -> BODEGA N°2 | U7: =IF($F$47="","",$F$47) -> EMBARQUE - LOTE 25106 | V7: =$F$103 -> 2029.7122 | W7: =$G$103 -> 0 | IG7: En espera de muelle por eslora | IH7: BOLIVIA IMPORTACION | II7: EMBARQUE DIRECTO | IJ7: MANUEL GALLEGOS | IL7: OPERADOR ELEVADORA 07 | IM7: ELEVADORA 07 TNS. | IO7: ALQUILER DE PORTACONTENEDORES | IR7: CANOPUS | IS7: CAMIONES | IY7: ALVAREZ VERGARA, MANUEL | IZ7: OP. FAJA | JB7: BUSTAMANTE, PAUL | JC7: GAVIERO
L8: Ag. Marítimo | N8: =SUMIF('Serv. no Conf. - Horas Muertas'!$N$18:$N$66,"NAVIERO",'Serv. no Conf. - Horas Muertas'!$F$18:$F$66) -> 0.18680556 | P8: Cliente | R8: =SUMIF('Serv. no Conf. - Horas Muertas'!$O$72:$O$225,P8,'Serv. no Conf. - Horas Muertas'!$F$72:$F$225) -> 0 | T8: =IF($H$46="","",$H$46) -> BODEGA N°3 | U8: =IF($H$47="","",$H$47) -> EMBARQUE | V8: =$H$103 -> 0 | W8: =$I$103 -> 0 | IG8: Inspecciones fitosanitarias | IH8: CABOTAJE | IJ8: FABRICIO RIVERA | IL8: OPERADOR ELEVADORA 13 | IM8: ELEVADORA 13 TNS. | IO8: SUMINISTRO DE AGUA | IR8: AGUNSA | IS8: TRIMADORA | IY8: AMAO MAMANI ENRIQUE POMPEYO | IZ8: OPERADOR | JB8: PEÑARANDA DEL CARPIO, HELBERT | JC8: GAVIERO
B9: Arribo | C9: 45933.438 | F9: Bandera | H9: PANAMA | L9: Ag. Estiba | N9: =SUMIF('Serv. no Conf. - Horas Muertas'!$N$18:$N$66,"ESTIBA",'Serv. no Conf. - Horas Muertas'!$F$18:$F$66) -> 0.18055556 | P9: Empresa Practicaje | R9: =SUMIF('Serv. no Conf. - Horas Muertas'!$O$72:$O$225,P9,'Serv. no Conf. - Horas Muertas'!$F$72:$F$225) -> 0 | T9: =IF($J$46="","",$J$46) -> BODEGA N°4 | U9: =IF($J$47="","",$J$47) -> EMBARQUE - LOTE 25107 | V9: =$J$103 -> 2060.0262 | W9: =$K$103 -> 0 | IG9: Alistamiento de bodegas | IH9: TRANSBORDO | IJ9: JOSE CACERES | IL9: OPERADOR ELEVADORA 20 | IM9: ELEVADORA 20 TNS. | IO9: CONEXIÓN DE MANGAS | IR9: TRAMARSA | IY9: ANDIA ANTONY | IZ9: TARJADOR | JB9: ZEGARRA MEDINA, MIKI | JC9: GAVIERO
B10: Atraque | C10: 45938.73 | F10: Pto. Origen | H10: CHILE | L10: Cliente | N10: =SUMIF('Serv. no Conf. - Horas Muertas'!$N$18:$N$66,"CLIENTE",'Serv. no Conf. - Horas Muertas'!$F$18:$F$66) -> 0.14791667 | P10: Empresa Practicaje / Empresa Remolcaje | R10: =SUMIF('Serv. no Conf. - Horas Muertas'!$O$72:$O$225,P10,'Serv. no Conf. - Horas Muertas'!$F$72:$F$225) -> 0 | T10: =IF($L$46="","",$L$46) -> BODEGA N°5 | U10: =IF($L$47="","",$L$47) -> EMBARQUE - LOTE 25108 | V10: =$L$103 -> 2200.218 | W10: =$M$103 -> 0 | IG10: Apertura de estación de prácticos | IJ10: ISABEL PORTUGAL | IL10: OPERADOR MAGNUM | IM10: MAGNUM / VOLQUETE | IO10: PERSONAL A LA ORDEN | IR10: SOUTH SHIPPING | IY10: ARAGON VALDEZ YHOCINIO MANUEL | IZ10: OPERADOR | JB10: ZEGARRA MEDINA, REMIGIO | JC10: GAVIERO
B11: Hora de Inicio de Carga | C11: 45938.951 | F11: Pto. Destino | H11: BAHIA | L11: Refrigerio | N11: =SUMIF('Serv. no Conf. - Horas Muertas'!$N$18:$N$66,"REFRIGERIO",'Serv. no Conf. - Horas Muertas'!$F$18:$F$66) -> 0 | P11: Empresa Remolcaje | R11: =SUMIF('Serv. no Conf. - Horas Muertas'!$O$72:$O$225,P11,'Serv. no Conf. - Horas Muertas'!$F$72:$F$225) -> 0 | T11: =IF($N$46="","",$N$46) | U11: =IF($N$47="","",$N$47) | V11: =$N$103 -> 0 | W11: =$O$103 -> 0 | IG11: Muelle disponible | IJ11: ELIZABETH CANAZA | IL11: OPERADOR BOBCAT | IM11: BOBCAT | IO11: MOVILIZACION DE CONT. VIA MUELLE | IR11: OCEANO | IY11: ARCE MAMANI ERLY RICHARD | IZ11: OPERADOR | JB11: ZEGARRA GRANDA, AYMAR | JC11: GAVIERO
B12: Hora de Termino de Carga | C12: 45940.146 | F12: Muelle | H12: F | L12: Fuerza Mayor | N12: =SUMIF('Serv. no Conf. - Horas Muertas'!$N$18:$N$66,"FUERZA MAYOR",'Serv. no Conf. - Horas Muertas'!$F$18:$F$66) -> 0 | P12: Fuerza mayor | R12: =SUMIF('Serv. no Conf. - Horas Muertas'!$O$72:$O$225,P12,'Serv. no Conf. - Horas Muertas'!$F$72:$F$225) -> 0 | T12: =IF($P$46="","",$P$46) | U12: =IF($P$47="","",$P$47) | V12: =$P$103 -> 0 | W12: =$Q$103 -> 0 | IG12: Secuencia de maniobras | IL12: OPERADOR FAJA F | IM12: FAJA TRANSPORTADORA MUELLE F | IO12: MOVILIZACION DE CONT. MUELLE / ZONA | IR12: CITIKOLD | IY12: AROCUTIPA MAMANI OSCAR | IZ12: OPERADOR | JB12: FLORES STEVENS | JC12: GAVIERO
B13: Desatraque | C13: 45940.225 | F13: Hrs. Efectivas | H13: 0.875 | K13: =+H13*24 -> 21 | L13: Atraque | N13: =SUMIF('Serv. no Conf. - Horas Muertas'!$N$18:$N$66,"ATRAQUE",'Serv. no Conf. - Horas Muertas'!$F$18:$F$66) -> 0.040972222 | P13: Inspectora | R13: =SUMIF('Serv. no Conf. - Horas Muertas'!$O$72:$O$225,P13,'Serv. no Conf. - Horas Muertas'!$F$72:$F$225) -> 0 | T13: =IF($R$46="","",$R$46) | U13: =IF($R$47="","",$R$47) | V13: =$R$103 -> 0 | W13: =$AA$103 -> 0 | IG13: Otros | IL13: OPERADOR FAJA C | IM13: FAJA TRANSPORTADORA MUELLE C | IO13: ALQUILER DE TRUCK MOVIL | IR13: SERPAC | IY13: BALLON JHOSELIN | IZ13: TARJADOR | JC13: GAVIERO
B14: Ag. Marítimo | C14: TRANSTOTAL | F14: Hrs. Amarradero | H14: =IF(C13="",0,C13-C10) -> 1.4951389 | K14: =+H14*24 -> 35.883333 | L14: Desatraque | N14: =SUMIF('Serv. no Conf. - Horas Muertas'!$N$18:$N$66,"DESATRAQUE",'Serv. no Conf. - Horas Muertas'!$F$18:$F$66) -> 0.0083333333 | P14: Tisur | R14: =SUMIF('Serv. no Conf. - Horas Muertas'!$O$72:$O$225,P14,'Serv. no Conf. - Horas Muertas'!$F$72:$F$225) -> 0 | T14: =IF($AB$46="","",$AB$46) | U14: =IF($AB$47="","",$AB$47) | V14: =$AB$103 -> 0 | W14: =$AC$103 -> 0 | IL14: OPERADOR BARREDORA | IM14: BARREDORA | IO14: AQLUILER DE BALANZA | IR14: FAPOSAC | IY14: BALLON RIVERA JOE BRYAN | IZ14: TARJADOR | JC14: GAVIERO
B15: Ag. Estiba | C15: TRAMARSA | F15: Rend. Tn/Hrs. Amarradero | H15: =IF(D43=0," ",D43/(H14*24)) -> 1226.3365 | N15: =SUM(N7:N14) -> 0.62013889 | T15: =IF($AD$46="","",$AD$46) | U15: =IF($AD$47="","",$AD$47) | V15: =$AD$103 -> 0 | W15: =$AE$103 -> 0 | IL15: OPERADOR DE GRUA GOTTWALD | IM15: GRUA GOTTWALD | IO15: MOVILIZACION DE TUBERIAS Y MANGAS | IR15: AGENCIA MARITIMA B&M SAC | IY15: BALLON DENIS | IZ15: OPERADOR
F16: Rend. Un/Hrs. Amarradero | H16: =IF(E43=0," ",E43/(H14*24)) | R16: =SUM(R7:R14) -> 0 | IL16: OPERADOR DE GRUA LIEBHERR | IM16: GRUA LIEBHERR | IO16: INGRESO SUMINISTRO AGUA | IR16: TRANSMERIDAN | IY16: CACERES QUEA, JOSE | IZ16: OP. FAJA
B17: Atraque Planificado en JJOO | C17: 45938.708 | F17: Hrs. Operacion | H17: =IF(C13="",0,C12-C11) -> 1.1944444 | K17: =+H17*24 -> 28.666667 | L17: =K13+'Serv. no Conf. - Horas Muertas'!G67 -> 28.666667 | M17: =+N15+H13 -> 1.4951389 | IL17: OPERADOR PORTACONTENEDOR LLENOS | IM17: PORTACONTENEDORES LLENOS | IO17: TORRE VIGAN | IR17: CALL SHIPPING | IY17: CANAZA PROVINCIA, ELIZABETH | IZ17: OP. FAJA
B18: Inicio de op. Planificado en JJOO | C18: 45938.833 | AA18: =IF($AD$47="","",$AD$47) | IL18: OPERADOR PORTACONTENEDOR VACIOS | IM18: PORTACONTENEDORES VACIOS | IO18: TORRE BHULER | IR18: J&R SERVICIOS | IY18: CARI MAMANI VICTOR MANUEL | IZ18: OPERADOR
B19: Termino de op. Planificado en JJOO | C19: 45940.083 | IL19: OPERADOR TRUCK MOVIL | IM19: TRUCK MOVIL | IO19: DESECHOS ORGANICOS | IR19: COSMOS | IY19: CAVIDES CHAVEZ ALBY FRENZY | IZ19: OP. FAJA
B20: Desatraque Planificado en JJOO | C20: 45940.097 | IL20: OPERADOR MANLIFT | IM20: MANLIFT | IO20: PERSONAL A LA ORDEN | IR20: TPP | IY20: CHALCO PUMA ALEXANDER | IZ20: OPERADOR
B21: Motivo de espera en Bahía | C21: Alistamiento de carga
IL22: BOTONERO TORRE VIGAN | IM22: TORRE VIGAN | IO22: OCUPACION DE ESPACIO | IR22: TRASMERIDIAN | IY22: CHAMBI DIAZ PABLO MARTIN | IZ22: OPERADOR
B23: NRO IMO | C23: 9561942 | IL23: SUPERVISOR DE MUELLE | IR23: IAN TAYLOR | IY23: CHECA MILAGROS | IZ23: TARJADOR
B24: Nombre de Línea Naviera | C24: SIN LINEA NAVIERA | IL24: TARJADOR | IY24: CHOQUECONZA OROCHE DAVID | IZ24: OP. FAJA
B25: Tipo de Tráfico (LINNER / TRAMP) | C25: TRAMP | IL25: RIGGER GOTTWALD | IM25: GRUA GOTTWALD | IY25: CHOQUEHUANCA VILCA, RAQUEL | IZ25: OP. FAJA
IL26: RIGGER LIEBHERR | IM26: GRUA LIEBHERR | IY26: COARICONA MENDOZA JOSE LUIS | IZ26: OPERADOR
B27: Libre Plática (Según APN) | C27: 45929.865 | IL27: GAVIERO | IY27: CONDORI JHON | IZ27: OPERADOR
IL28: OPERADOR DE GRUA TEREX | IY28: CUENTAS LARENAS JONATHAN ELVIS JUAN | IZ28: OPERADOR
B29: Inicio de Operación (Estibadores a bordo de nave) | C29: 45909.781 | IL29: OPERADOR DE BARREDORA | IM29: BARREDORA | IY29: CUEVAS CUTIMBO MAYERLI IDALIA | IZ29: TARJADOR
B30: Término de Operación (Retiro de estibadores de nave) | C30: 45940.188 | IY30: ELIZALDE MELGAR MARIO FAUSTINO | IZ30: OPERADOR
B31: Hora Práctico desembarca nave después del atraque | C31: 45908.776
B32: Hora Autorización Inicio Operaciones APN | C32: 45909.865
B33: Hora Autorización Zarpe APN | C33: 45909.872
IY35: ESCOBEDO FELIX | IZ35: TARJADOR
B36: REGIMEN | C36: OPERACIÓN | D36: PESO | E36: CANTIDAD | F36: PRODUCTO | I36: CLIENTE (S) | IY36: FERNANDEZ VARGAS JAVIER ALEJANDRO | IZ36: OPERADOR
B37: EXPORTACION | C37: EMBARQUE INDIRECTO | D37: 44005.04 | F37: CONCENTRADO DE COBRE | I37: LAS BAMBAS | IY37: FLORES TINTAYA LUIS VICTOR | IZ37: OPERADOR
IY38: HUERTA FEBRES JORGE | IZ38: SUP. MUELLE
IT39: Bodegas Tipo Cajon | IU39: B 1 | IY39: LIMA APAZA JUAN MIGUEL | IZ39: OPERADOR
IT40: Bodegas con Wines | IU40: B 2 | IY40: LUQUE JESUS | IZ40: TARJADOR
IU41: B 3 | IY41: LUQUE HERRERA ALYSSON BRIGITE | IZ41: TARJADOR
IO42: Botoneros | IU42: B 4 | IY42: MARROQUIN LLERENA OSCAR | IZ42: SUP. MUELLE
B43: TOTALES | D43: =SUM(D37:D42) -> 44005.04 | E43: =SUM(E37:E41) -> 0 | F43: =IF(D43=AF63,"Ok","Diferencia de pesos") -> Ok | H43: =IF(E43=AG63,"Ok","Diferencia de cantidades") -> Ok | I43: Peso Draft | IU43: B 5 | IY43: MARTINEZ SOLIS NORMA ELENA | IZ43: TARJADOR
...

Sheet Hoja1
A4: Recalada | B4: Nave | C4: Tiempo Efectivo | D4: Tisur | E4: TM Agente Maritimo | F4: TM Agente Estiba | G4: Cliente | H4: Estibadores | I4: Refrigerio | J4: Agencia Aduana | K4: Esperando Desatraque | L4: Falta Camiones | M4: Lluvia | N4: Por Orden Capitan | O4: Esperando Atraque | P4: Total Tiempo Muerto | Q4: Nave-Inicio Operación | R4: Nave-Termino operación | S4: Libre de platica (según APN) | T4: Atraque Planif | U4: Desatraque Planif. | V4: Inicio Planif. | W4: Termino Planif. | X4: Fecha Arribo | Y4: Nro de Imo | Z4: Nombre de Linea naviera | AA4: Tipo de trafico (Linner / Tramp) | AB4: Estibadores a bordo de nave | AC4: Retiro de estibadores de nave
A5: =Informe!D6 -> 10841 | B5: =Informe!D5 -> SKY KNIGHT | C5: =Informe!H13 -> 0.875 | D5: =Informe!N7 -> 0.055555556 | E5: =Informe!N8 -> 0.18680556 | F5: =Informe!N9 -> 0.18055556 | G5: =Informe!N10 -> 0.14791667 | I5: =Informe!N11 -> 0 | K5: =Informe!N14 -> 0.0083333333 | M5: =Informe!N12 -> 0 | O5: =Informe!N13 -> 0.040972222 | P5: =SUM(D5:O5) -> 0.62013889 | Q5: =Informe!C11 -> 45938.951 | R5: =Informe!C12 -> 45940.146 | S5: =Informe!C27 -> 45929.865 | T5: =Informe!C17 -> 45938.708 | U5: =Informe!C20 -> 45940.097 | V5: =Informe!C18 -> 45938.833 | W5: =Informe!C19 -> 45940.083 | X5: =Informe!C9 -> 45933.438 | Y5: =Informe!C23 -> 9561942 | Z5: =Informe!C24 -> SIN LINEA NAVIERA | AA5: =Informe!C25 -> TRAMP | AB5: =Informe!C29 -> 45909.781 | AC5: =Informe!C30 -> 45940.188

Sheet Serv. no Conf. - Horas Muertas
B4: FORSUR-O-0050 | N4: REV-14
B5: SERVICIO NO CONFORME
B6: Motivo | E6: Situación | G6: Causa | K6: Acción Inmediata | IS6: OPERATIVAS | IT6: CLIENTE | IU6: CONFORME
B7: Amarre y Desamarre | E7: CONFORME | IS7: TERCEROS | IT7: ESTIBA | IU7: NO CONFORME
B8: Alquiler de Amarradero | E8: CONFORME | IS8: TISUR | IT8: NAVIERO
B9: Uso de Muelle | E9: CONFORME | IT9: TISUR
B10: Traccion | E10: CONFORME | IT10: REFRIGERIO
B11: Manipuleo | E11: CONFORME | IT11: FUERZA MAYOR
B12: Alquiler de Equipos | E12: CONFORME | IT12: ATRAQUE
IT13: DESATRAQUE
B14: TIEMPOS PRE Y POST OPERACIÓN
B15: Registro de Tiempos de Recepcion y Despacho de la Nave
B16: Jornada | C16: Fecha | D16: Paradas | F16: Total | G16: Detalle | N16: Imputable | O16: Imputable APN
D17: Inicio | E17: Termino
B18: DIA | C18: 45938 | D18: 0.72986111 | E18: 0.77083333 | F18: =IF(D18="","",E18-D18) -> 0.040972222 | G18: ATRAQUE | N18: ATRAQUE
B19: DIA | C19: 45938 | D19: 0.77083333 | E19: 0.78125 | F19: =IF(D19="","",E19-D19) -> 0.010416667 | G19: AUTORIDADES ABORDO | N19: NAVIERO
B20: DIA | C20: 45938 | D20: 0.78125 | E20: 0.78819444 | F20: =IF(D20="","",E20-D20) -> 0.0069444444 | G20: CONFERENCIA | N20: NAVIERO
B21: DIA | C21: 45938 | D21: 0.78819444 | E21: 0.85416667 | F21: =IF(D21="","",E21-D21) -> 0.065972222 | G21: APERTURA E INSPECCION DE BODEGAS ( RETIRO DE CILINDROS EN BODEGA N° 4 ) | N21: CLIENTE
B22: NOCHE | C22: 45938 | D22: 0.85416667 | E22: 0.9375 | F22: =IF(D22="","",E22-D22) -> 0.083333333 | G22: MANIOBRA DE SEPARACION DE NAVE AL MUELLE PARA POSICIONAR SHIPLOADER | N22: NAVIERO
B23: NOCHE | C23: 45938 | D23: 0.9375 | E23: 0.95138889 | F23: =IF(D23="","",E23-D23) -> 0.013888889 | G23: PRUEBA DE ENCLAVAMIENTO Y ESPERA DE CARGA | N23: TISUR
F24: =IF(D24="","",E24-D24)
F25: =IF(D25="","",E25-D25)
F26: =IF(D26="","",E26-D26)
B27: NOCHE | C27: 45939 | D27: 0.14583333 | E27: 0.15277778 | F27: =IF(D27="","",E27-D27) -> 0.0069444444 | G27: CORRIDA DE FAJAS EN VACIO / LIMPIEZA DE CHUTES | N27: TISUR
B28: NOCHE | C28: 45939 | D28: 0.15277778 | E28: 0.20416667 | F28: =IF(D28="","",E28-D28) -> 0.051388889 | G28: A LA ESPERA DE PRACTICO | N28: NAVIERO
B29: NOCHE | C29: 45939 | D29: 0.20416667 | E29: 0.21666667 | F29: =IF(D29="","",E29-D29) -> 0.0125 | G29: DESPACHO DE NAVE | N29: CLIENTE
B30: NOCHE | C30: 45939 | D30: 0.21666667 | E30: 0.225 | F30: =IF(D30="","",E30-D30) -> 0.0083333333 | G30: DESATRAQUE | N30: DESATRAQUE
F31: =IF(D31="","",E31-D31)
F32: =IF(D32="","",E32-D32)
F33: =IF(D33="","",E33-D33)
F34: =IF(D34="","",E34-D34)
D35: TIEMPO MUERTO | F35: =SUM(F18:F34) -> 0.30069444
B37: REGISTRO DE PARADAS DE TODAS LAS BODEGAS
B38: Jornada | C38: Fecha | D38: Paradas | F38: Total | G38: Detalle | N38: Imputable | O38: Imputable APN
D39: Inicio | E39: Termino
B40: NOCHE | C40: 45938 | D40: 0.97222222 | E40: 0.97916667 | F40: =+E40-D40 -> 0.0069444444 | G40: DETECTOR DE METALES FAJA # 18 | N40: CLIENTE
B41: NOCHE | C41: 45938 | D41: 0.99305556 | E41: 1 | F41: =+E41-D41 -> 0.0069444444 | G41: DETECTOR DE METALES FAJA # 18 | N41: CLIENTE
B42: NOCHE | C42: 45938 | D42: 0.14930556 | E42: 0.16666667 | F42: =+E42-D42 -> 0.017361111 | G42: CAMBIO DE BODEGA DE LA 4 A LA 2 | N42: ESTIBA
B43: NOCHE | C43: 45938 | D43: 0.16666667 | E43: 0.20138889 | F43: =+E43-D43 -> 0.034722222 | G43: AJUSTE DE CABOS | N43: NAVIERO
B44: NOCHE | C44: 45938 | D44: 0.20138889 | E44: 0.20486111 | F44: =+E44-D44 -> 0.0034722222 | G44: EN ESPERA DE CARGA Y REINICIO DE EMBARQUE | N44: TISUR
...

Sheet CHECKLIST LIQU PELIGROSOS
A2: FORSUR-O-0050 | F2: REVISION 14
B4: FECHA: | D4: RECALADA
B5: NAVE:
B6: AG. MARITIMA | D6: AG. ESTIBA
A7: LISTA DE VERIFICACION DE SEGURIDAD PARA OPERACIONES CON CARGA LIQUIDA PELIGROSA
A9: ITEM | B9: DESCRIPCION | C9: BUENO | D9: MALO | E9: NO HAY | F9: OBSERVACIONES
A10: 1 | B10: ILUMINACION EN LA ZONA DE MANIOBRA
A11: 2 | B11: AROS SALVAVIDAS
A12: 3 | B12: EQUIPOS DE LUCHA CONTRA INCENCIOS
A13: 4 | B13: LONA ENTRE LA NAVE Y EL MUELLE
A14: 5 | B14: REGIMEN DE DESCARGA ESTABLECIDO
A15: 6 | B15: REGIMEN DE DESCARGA MAXIMO
A16: 7 | B16: REGIMEN DE DESCARGA MINIMO
A17: 8 | B17: AVISOS / SEÑALIZACION
A18: 9 | B18: ESCALA CON RED
A19: 10 | B19: GUARDIA PERMANENTE
A20: 11 | B20: MANIFOLD DE ACIDUCTO
A21: 12 | B21: GUARDIAS DE SEGURIDAD
... A31: 22 | B31: KIT ANTIDERRAME
A33: OBSERVACIONES: | B33: UNIDADES DE LUCHA CONTRA INCENDIOS ASIGNADAS EN ZONA DE DESCARGA
A42: OPERACIONES | E42: SEGURIDAD
